Workbook

Sheet Sales
A1: Sales ID | B1: Product Serial # | C1: Price | D1: Cost | E1: Date | F1: Location: Country shipped to
A2: S-00001 | B2: P-100001 | C2: 200 | D2: =IF(B2="","",IFERROR(_xludf.XLOOKUP(_xludf.XLOOKUP(B2,Inventory!$A:$A,Inventory!$B:$B),Blades!$A:$A,Blades!$C:$C)+_xludf.XLOOKUP(_xludf.XLOOKUP(B2,Inventory!$A:$A,Inventory!$C:$C),Motor!$A:$A,Motor!$C:$C)+_xludf.XLOOKUP(_xludf.XLOOKUP(B2,Inventory!$A:$A,Inventory!$D:$D),Frame!$A:$A,Frame!$C:$C)+#REF!,"")) | E2: 43831 | F2: Australia
A3: S-00002 | B3: P-100002 | C3: 200 | D3: =IF(B3="","",IFERROR(_xludf.XLOOKUP(_xludf.XLOOKUP(B3,Inventory!$A:$A,Inventory!$B:$B),Blades!$A:$A,Blades!$C:$C)+_xludf.XLOOKUP(_xludf.XLOOKUP(B3,Inventory!$A:$A,Inventory!$C:$C),Motor!$A:$A,Motor!$C:$C)+_xludf.XLOOKUP(_xludf.XLOOKUP(B3,Inventory!$A:$A,Inventory!$D:$D),Frame!$A:$A,Frame!$C:$C)+#REF!,"")) | E3: 43832 | F3: Canada
A4: S-00003 | B4: P-100003 | C4: 200 | D4: =IF(B4="","",IFERROR(_xludf.XLOOKUP(_xludf.XLOOKUP(B4,Inventory!$A:$A,Inventory!$B:$B),Blades!$A:$A,Blades!$C:$C)+_xludf.XLOOKUP(_xludf.XLOOKUP(B4,Inventory!$A:$A,Inventory!$C:$C),Motor!$A:$A,Motor!$C:$C)+_xludf.XLOOKUP(_xludf.XLOOKUP(B4,Inventory!$A:$A,Inventory!$D:$D),Frame!$A:$A,Frame!$C:$C)+#REF!,"")) | E4: 43834 | F4: Australia
A5: S-00004 | B5: P-100004 | C5: 200 | D5: =IF(B5="","",IFERROR(_xludf.XLOOKUP(_xludf.XLOOKUP(B5,Inventory!$A:$A,Inventory!$B:$B),Blades!$A:$A,Blades!$C:$C)+_xludf.XLOOKUP(_xludf.XLOOKUP(B5,Inventory!$A:$A,Inventory!$C:$C),Motor!$A:$A,Motor!$C:$C)+_xludf.XLOOKUP(_xludf.XLOOKUP(B5,Inventory!$A:$A,Inventory!$D:$D),Frame!$A:$A,Frame!$C:$C)+#REF!,"")) | E5: 43834 | F5: Canada
A6: S-00005 | B6: P-100005 | C6: 200 | D6: =IF(B6="","",IFERROR(_xludf.XLOOKUP(_xludf.XLOOKUP(B6,Inventory!$A:$A,Inventory!$B:$B),Blades!$A:$A,Blades!$C:$C)+_xludf.XLOOKUP(_xludf.XLOOKUP(B6,Inventory!$A:$A,Inventory!$C:$C),Motor!$A:$A,Motor!$C:$C)+_xludf.XLOOKUP(_xludf.XLOOKUP(B6,Inventory!$A:$A,Inventory!$D:$D),Frame!$A:$A,Frame!$C:$C)+#REF!,"")) | E6: 43836 | F6: Canada
A7: S-00006 | B7: P-100006 | C7: 200 | D7: =IF(B7="","",IFERROR(_xludf.XLOOKUP(_xludf.XLOOKUP(B7,Inventory!$A:$A,Inventory!$B:$B),Blades!$A:$A,Blades!$C:$C)+_xludf.XLOOKUP(_xludf.XLOOKUP(B7,Inventory!$A:$A,Inventory!$C:$C),Motor!$A:$A,Motor!$C:$C)+_xludf.XLOOKUP(_xludf.XLOOKUP(B7,Inventory!$A:$A,Inventory!$D:$D),Frame!$A:$A,Frame!$C:$C)+#REF!,"")) | E7: 43840 | F7: Japan
A8: S-00007 | B8: P-100007 | C8: 200 | D8: =IF(B8="","",IFERROR(_xludf.XLOOKUP(_xludf.XLOOKUP(B8,Inventory!$A:$A,Inventory!$B:$B),Blades!$A:$A,Blades!$C:$C)+_xludf.XLOOKUP(_xludf.XLOOKUP(B8,Inventory!$A:$A,Inventory!$C:$C),Motor!$A:$A,Motor!$C:$C)+_xludf.XLOOKUP(_xludf.XLOOKUP(B8,Inventory!$A:$A,Inventory!$D:$D),Frame!$A:$A,Frame!$C:$C)+#REF!,"")) | E8: 43841 | F8: Canada
A9: S-00008 | B9: P-100008 | C9: 200 | D9: =IF(B9="","",IFERROR(_xludf.XLOOKUP(_xludf.XLOOKUP(B9,Inventory!$A:$A,Inventory!$B:$B),Blades!$A:$A,Blades!$C:$C)+_xludf.XLOOKUP(_xludf.XLOOKUP(B9,Inventory!$A:$A,Inventory!$C:$C),Motor!$A:$A,Motor!$C:$C)+_xludf.XLOOKUP(_xludf.XLOOKUP(B9,Inventory!$A:$A,Inventory!$D:$D),Frame!$A:$A,Frame!$C:$C)+#REF!,"")) | E9: 43843 | F9: United States
A10: S-00009 | B10: P-100009 | C10: 200 | D10: =IF(B10="","",IFERROR(_xludf.XLOOKUP(_xludf.XLOOKUP(B10,Inventory!$A:$A,Inventory!$B:$B),Blades!$A:$A,Blades!$C:$C)+_xludf.XLOOKUP(_xludf.XLOOKUP(B10,Inventory!$A:$A,Inventory!$C:$C),Motor!$A:$A,Motor!$C:$C)+_xludf.XLOOKUP(_xludf.XLOOKUP(B10,Inventory!$A:$A,Inventory!$D:$D),Frame!$A:$A,Frame!$C:$C)+#REF!,"")) | E10: 43844 | F10: Canada
A11: S-00010 | B11: P-100010 | C11: 200 | D11: =IF(B11="","",IFERROR(_xludf.XLOOKUP(_xludf.XLOOKUP(B11,Inventory!$A:$A,Inventory!$B:$B),Blades!$A:$A,Blades!$C:$C)+_xludf.XLOOKUP(_xludf.XLOOKUP(B11,Inventory!$A:$A,Inventory!$C:$C),Motor!$A:$A,Motor!$C:$C)+_xludf.XLOOKUP(_xludf.XLOOKUP(B11,Inventory!$A:$A,Inventory!$D:$D),Frame!$A:$A,Frame!$C:$C)+#REF!,"")) | E11: 43846 | F11: Australia
A12: S-00011 | B12: P-100011 | C12: 200 | D12: =IF(B12="","",IFERROR(_xludf.XLOOKUP(_xludf.XLOOKUP(B12,Inventory!$A:$A,Inventory!$B:$B),Blades!$A:$A,Blades!$C:$C)+_xludf.XLOOKUP(_xludf.XLOOKUP(B12,Inventory!$A:$A,Inventory!$C:$C),Motor!$A:$A,Motor!$C:$C)+_xludf.XLOOKUP(_xludf.XLOOKUP(B12,Inventory!$A:$A,Inventory!$D:$D),Frame!$A:$A,Frame!$C:$C)+#REF!,"")) | E12: 43847 | F12: Mexico
A13: S-00012 | B13: P-100012 | C13: 200 | D13: =IF(B13="","",IFERROR(_xludf.XLOOKUP(_xludf.XLOOKUP(B13,Inventory!$A:$A,Inventory!$B:$B),Blades!$A:$A,Blades!$C:$C)+_xludf.XLOOKUP(_xludf.XLOOKUP(B13,Inventory!$A:$A,Inventory!$C:$C),Motor!$A:$A,Motor!$C:$C)+_xludf.XLOOKUP(_xludf.XLOOKUP(B13,Inventory!$A:$A,Inventory!$D:$D),Frame!$A:$A,Frame!$C:$C)+#REF!,"")) | E13: 43847 | F13: Australia
... A3271: S-03270 | B3271: P-103270 | C3271: 200 | D3271: =IF(B3271="","",IFERROR(_xludf.XLOOKUP(_xludf.XLOOKUP(B3271,Inventory!$A:$A,Inventory!$B:$B),Blades!$A:$A,Blades!$C:$C)+_xludf.XLOOKUP(_xludf.XLOOKUP(B3271,Inventory!$A:$A,Inventory!$C:$C),Motor!$A:$A,Motor!$C:$C)+_xludf.XLOOKUP(_xludf.XLOOKUP(B3271,Inventory!$A:$A,Inventory!$D:$D),Frame!$A:$A,Frame!$C:$C)+#REF!,"")) | E3271: 46387 | F3271: France

Sheet Inventory
A1: Product Serial # | B1: Blades Serial # | C1: Motor Serial # | D1: Frame Serial #
A2: P-100001 | B2: B-500001 | C2: M-700001 | D2: F-900001
A3: P-100002 | B3: B-500002 | C3: M-700002 | D3: F-900002
A4: P-100003 | B4: B-500003 | C4: M-700003 | D4: F-900003
A5: P-100004 | B5: B-500004 | C5: M-700004 | D5: F-900004
A6: P-100005 | B6: B-500005 | C6: M-700005 | D6: F-900005
A7: P-100006 | B7: B-500006 | C7: M-700006 | D7: F-900006
A8: P-100007 | B8: B-500007 | C8: M-700007 | D8: F-900007
A9: P-100008 | B9: B-500008 | C9: M-700008 | D9: F-900008
A10: P-100009 | B10: B-500009 | C10: M-700009 | D10: F-900009
A11: P-100010 | B11: B-500010 | C11: M-700010 | D11: F-900010
A12: P-100011 | B12: B-500011 | C12: M-700011 | D12: F-900011
... A3271: P-103270 | B3271: B-503270 | C3271: M-703270 | D3271: F-903270

Sheet Blades
A1: Blades Serial # | B1: Factory | C1: Unit Cost
A2: B-500001 | B2: Seattle WA | C2: =IF(B2="","",SUMIFS('Factory Costs'!$C:$C,'Factory Costs'!$A:$A,"Blades",'Factory Costs'!$B:$B,B2)) -> 34
A3: B-500002 | B3: Seattle WA | C3: =IF(B3="","",SUMIFS('Factory Costs'!$C:$C,'Factory Costs'!$A:$A,"Blades",'Factory Costs'!$B:$B,B3)) -> 34
A4: B-500003 | B4: Tacoma WA | C4: =IF(B4="","",SUMIFS('Factory Costs'!$C:$C,'Factory Costs'!$A:$A,"Blades",'Factory Costs'!$B:$B,B4)) -> 37
A5: B-500004 | B5: Seattle WA | C5: =IF(B5="","",SUMIFS('Factory Costs'!$C:$C,'Factory Costs'!$A:$A,"Blades",'Factory Costs'!$B:$B,B5)) -> 34
A6: B-500005 | B6: Seattle WA | C6: =IF(B6="","",SUMIFS('Factory Costs'!$C:$C,'Factory Costs'!$A:$A,"Blades",'Factory Costs'!$B:$B,B6)) -> 34
A7: B-500006 | B7: Seattle WA | C7: =IF(B7="","",SUMIFS('Factory Costs'!$C:$C,'Factory Costs'!$A:$A,"Blades",'Factory Costs'!$B:$B,B7)) -> 34
A8: B-500007 | B8: Seattle WA | C8: =IF(B8="","",SUMIFS('Factory Costs'!$C:$C,'Factory Costs'!$A:$A,"Blades",'Factory Costs'!$B:$B,B8)) -> 34
A9: B-500008 | B9: Vancouver WA | C9: =IF(B9="","",SUMIFS('Factory Costs'!$C:$C,'Factory Costs'!$A:$A,"Blades",'Factory Costs'!$B:$B,B9)) -> 42
A10: B-500009 | B10: Tacoma WA | C10: =IF(B10="","",SUMIFS('Factory Costs'!$C:$C,'Factory Costs'!$A:$A,"Blades",'Factory Costs'!$B:$B,B10)) -> 37
A11: B-500010 | B11: Vancouver WA | C11: =IF(B11="","",SUMIFS('Factory Costs'!$C:$C,'Factory Costs'!$A:$A,"Blades",'Factory Costs'!$B:$B,B11)) -> 42
A12: B-500011 | B12: Seattle WA | C12: =IF(B12="","",SUMIFS('Factory Costs'!$C:$C,'Factory Costs'!$A:$A,"Blades",'Factory Costs'!$B:$B,B12)) -> 34
A13: B-500012 | B13: Seattle WA | C13: =IF(B13="","",SUMIFS('Factory Costs'!$C:$C,'Factory Costs'!$A:$A,"Blades",'Factory Costs'!$B:$B,B13)) -> 34
... A3271: B-503270 | B3271: Seattle WA | C3271: =IF(B3271="","",SUMIFS('Factory Costs'!$C:$C,'Factory Costs'!$A:$A,"Blades",'Factory Costs'!$B:$B,B3271)) -> 34

Sheet Motor
A1: Motor Serial # | B1: Factory | C1: Unit Cost
A2: M-700001 | B2: Portland OR | C2: =IF(B2="","",SUMIFS('Factory Costs'!$C:$C,'Factory Costs'!$A:$A,"Motor",'Factory Costs'!$B:$B,B2)) -> 62
A3: M-700002 | B3: Portland OR | C3: =IF(B3="","",SUMIFS('Factory Costs'!$C:$C,'Factory Costs'!$A:$A,"Motor",'Factory Costs'!$B:$B,B3)) -> 62
A4: M-700003 | B4: Portland OR | C4: =IF(B4="","",SUMIFS('Factory Costs'!$C:$C,'Factory Costs'!$A:$A,"Motor",'Factory Costs'!$B:$B,B4)) -> 62
A5: M-700004 | B5: Denver CO | C5: =IF(B5="","",SUMIFS('Factory Costs'!$C:$C,'Factory Costs'!$A:$A,"Motor",'Factory Costs'!$B:$B,B5)) -> 72
A6: M-700005 | B6: Portland OR | C6: =IF(B6="","",SUMIFS('Factory Costs'!$C:$C,'Factory Costs'!$A:$A,"Motor",'Factory Costs'!$B:$B,B6)) -> 62
A7: M-700006 | B7: Portland OR | C7: =IF(B7="","",SUMIFS('Factory Costs'!$C:$C,'Factory Costs'!$A:$A,"Motor",'Factory Costs'!$B:$B,B7)) -> 62
A8: M-700007 | B8: Denver CO | C8: =IF(B8="","",SUMIFS('Factory Costs'!$C:$C,'Factory Costs'!$A:$A,"Motor",'Factory Costs'!$B:$B,B8)) -> 72
A9: M-700008 | B9: Portland OR | C9: =IF(B9="","",SUMIFS('Factory Costs'!$C:$C,'Factory Costs'!$A:$A,"Motor",'Factory Costs'!$B:$B,B9)) -> 62
A10: M-700009 | B10: Denver CO | C10: =IF(B10="","",SUMIFS('Factory Costs'!$C:$C,'Factory Costs'!$A:$A,"Motor",'Factory Costs'!$B:$B,B10)) -> 72
A11: M-700010 | B11: Denver CO | C11: =IF(B11="","",SUMIFS('Factory Costs'!$C:$C,'Factory Costs'!$A:$A,"Motor",'Factory Costs'!$B:$B,B11)) -> 72
A12: M-700011 | B12: Denver CO | C12: =IF(B12="","",SUMIFS('Factory Costs'!$C:$C,'Factory Costs'!$A:$A,"Motor",'Factory Costs'!$B:$B,B12)) -> 72
A13: M-700012 | B13: Denver CO | C13: =IF(B13="","",SUMIFS('Factory Costs'!$C:$C,'Factory Costs'!$A:$A,"Motor",'Factory Costs'!$B:$B,B13)) -> 72
... A3271: M-703270 | B3271: Denver CO | C3271: =IF(B3271="","",SUMIFS('Factory Costs'!$C:$C,'Factory Costs'!$A:$A,"Motor",'Factory Costs'!$B:$B,B3271)) -> 72

Sheet Frame
A1: Frame Serial # | B1: Factory | C1: Unit Cost
A2: F-900001 | B2: Dallas TX | C2: =IF(B2="","",SUMIFS('Factory Costs'!$C:$C,'Factory Costs'!$A:$A,"Frame",'Factory Costs'!$B:$B,B2)) -> 39
A3: F-900002 | B3: Dallas TX | C3: =IF(B3="","",SUMIFS('Factory Costs'!$C:$C,'Factory Costs'!$A:$A,"Frame",'Factory Costs'!$B:$B,B3)) -> 39
A4: F-900003 | B4: Richardson TX | C4: =IF(B4="","",SUMIFS('Factory Costs'!$C:$C,'Factory Costs'!$A:$A,"Frame",'Factory Costs'!$B:$B,B4)) -> 52
A5: F-900004 | B5: Plano TX | C5: =IF(B5="","",SUMIFS('Factory Costs'!$C:$C,'Factory Costs'!$A:$A,"Frame",'Factory Costs'!$B:$B,B5)) -> 45
A6: F-900005 | B6: Richardson TX | C6: =IF(B6="","",SUMIFS('Factory Costs'!$C:$C,'Factory Costs'!$A:$A,"Frame",'Factory Costs'!$B:$B,B6)) -> 52
A7: F-900006 | B7: Plano TX | C7: =IF(B7="","",SUMIFS('Factory Costs'!$C:$C,'Factory Costs'!$A:$A,"Frame",'Factory Costs'!$B:$B,B7)) -> 45
A8: F-900007 | B8: Richardson TX | C8: =IF(B8="","",SUMIFS('Factory Costs'!$C:$C,'Factory Costs'!$A:$A,"Frame",'Factory Costs'!$B:$B,B8)) -> 52
A9: F-900008 | B9: Dallas TX | C9: =IF(B9="","",SUMIFS('Factory Costs'!$C:$C,'Factory Costs'!$A:$A,"Frame",'Factory Costs'!$B:$B,B9)) -> 39
A10: F-900009 | B10: Dallas TX | C10: =IF(B10="","",SUMIFS('Factory Costs'!$C:$C,'Factory Costs'!$A:$A,"Frame",'Factory Costs'!$B:$B,B10)) -> 39
A11: F-900010 | B11: Plano TX | C11: =IF(B11="","",SUMIFS('Factory Costs'!$C:$C,'Factory Costs'!$A:$A,"Frame",'Factory Costs'!$B:$B,B11)) -> 45
A12: F-900011 | B12: Dallas TX | C12: =IF(B12="","",SUMIFS('Factory Costs'!$C:$C,'Factory Costs'!$A:$A,"Frame",'Factory Costs'!$B:$B,B12)) -> 39
A13: F-900012 | B13: Plano TX | C13: =IF(B13="","",SUMIFS('Factory Costs'!$C:$C,'Factory Costs'!$A:$A,"Frame",'Factory Costs'!$B:$B,B13)) -> 45
... A3271: F-903270 | B3271: Plano TX | C3271: =IF(B3271="","",SUMIFS('Factory Costs'!$C:$C,'Factory Costs'!$A:$A,"Frame",'Factory Costs'!$B:$B,B3271)) -> 45

Sheet Returns
A1: Product Serial # | B1: Defect: y/n | C1: Defect Part | D1: Refund Amount | E1: Return Date
A2: P-100026 | B2: Y | C2: Blades | D2: 200 | E2: 43877
A3: P-100027 | B3: N | D3: 200 | E3: 43936
A4: P-100045 | B4: Y | C4: Frame | D4: 200 | E4: 43966
A5: P-100046 | B5: Y | C5: Frame | D5: 200 | E5: 43958
A6: P-100056 | B6: Y | C6: Blades | D6: 200 | E6: 43949
A7: P-100087 | B7: Y | C7: Blades | D7: 200 | E7: 44035
A8: P-100099 | B8: Y | C8: Frame | D8: 200 | E8: 44037
A9: P-100154 | B9: Y | C9: Blades | D9: 200 | E9: 44074
A10: P-100172 | B10: N | D10: 200 | E10: 44173
A11: P-100174 | B11: Y | C11: Blades | D11: 200 | E11: 44164
A12: P-100214 | B12: Y | C12: Motor | D12: 200 | E12: 44179
A13: P-100232 | B13: Y | C13: Blades | D13: 200 | E13: 44221
A14: P-100234 | B14: Y | C14: Blades | D14: 200 | E14: 44221
A15: P-100236 | B15: Y | C15: Blades | D15: 200 | E15: 44222
A16: P-100242 | B16: Y | C16: Blades | D16: 200 | E16: 44210
A17: P-100263 | B17: Y | C17: Blades | D17: 200 | E17: 44241
A18: P-100266 | B18: Y | C18: Motor | D18: 200 | E18: 44298
A19: P-100271 | B19: Y | C19: Blades | D19: 200 | E19: 44252
A20: P-100288 | B20: N | D20: 200 | E20: 44289
A21: P-100292 | B21: Y | C21: Frame | D21: 200 | E21: 44304
A22: P-100295 | B22: Y | C22: Frame | D22: 200 | E22: 44328
A23: P-100331 | B23: Y | C23: Frame | D23: 200 | E23: 44348
A24: P-100340 | B24: Y | C24: Blades | D24: 200 | E24: 44324
A25: P-100367 | B25: Y | C25: Motor | D25: 200 | E25: 44413
A26: P-100371 | B26: Y | C26: Motor | D26: 200 | E26: 44385
A27: P-100390 | B27: Y | C27: Motor | D27: 200 | E27: 44445
A28: P-100399 | B28: Y | C28: Motor | D28: 200 | E28: 44417
A29: P-100404 | B29: Y | C29: Frame | D29: 200 | E29: 44418
A30: P-100405 | B30: Y | C30: Blades | D30: 200 | E30: 44461
A31: P-100421 | B31: N | D31: 200 | E31: 44406
A32: P-100442 | B32: Y | C32: Motor | D32: 200 | E32: 44465
A33: P-100450 | B33: Y | C33: Frame | D33: 200 | E33: 44428
A34: P-100460 | B34: N | D34: 200 | E34: 44439
A35: P-100479 | B35: Y | C35: Blades | D35: 200 | E35: 44541
A36: P-100492 | B36: Y | C36: Frame | D36: 200 | E36: 44500
A37: P-100511 | B37: Y | C37: Blades | D37: 200 | E37: 44578
A38: P-100519 | B38: Y | C38: Frame | D38: 200 | E38: 44521
A39: P-100529 | B39: Y | C39: Frame | D39: 200 | E39: 44524
A40: P-100531 | B40: Y | C40: Blades | D40: 200 | E40: 44579
...

Sheet Factory Costs
A1: Component | B1: Factory | C1: Unit Cost
A2: Blades | B2: Seattle WA | C2: 34
A3: Blades | B3: Vancouver WA | C3: 42
A4: Blades | B4: Tacoma WA | C4: 37
A5: Motor | B5: Portland OR | C5: 62
A6: Motor | B6: Denver CO | C6: 72
A7: Frame | B7: Dallas TX | C7: 39
A8: Frame | B8: Richardson TX | C8: 52
A9: Frame | B9: Plano TX | C9: 45
